<?xml version="1.0" ?>
<!-- =================================================================================== -->
<!-- |    This document was autogenerated by xacro from my_bot.urdf.xacro              | -->
<!-- |    EDITING THIS FILE BY HAND IS NOT RECOMMENDED                                 | -->
<!-- =================================================================================== -->
<robot name="my_bot">
  <!-- =========================================================
       MATERIALES
       ========================================================= -->
  <material name="chassis_color">
    <color rgba="0.3 0.5 0.8 1"/>
  </material>
  <material name="lidar_color">
    <color rgba="1.0 0.5 0.5 1"/>
  </material>
  <material name="wheel_color">
    <color rgba="0.6 0.6 0.6 1"/>
  </material>
  <!-- =========================================================
       CHASIS
       ========================================================= -->
  <link name="base_link">
    <!-- Visual for the main body -->
    <visual>
      <geometry>
        <box rpy="0 0 0" size="0.25 0.3 0.06"/>
      </geometry>
      <origin xyz="0 0 0.08"/>
      <material name="chassis_color"/>
    </visual>
    <!-- Visual for the LiDAR support bracket (COSMETIC ONLY) -->
    <visual name="lidar_support_visual">
      <geometry>
        <box size="0.035 0.05 0.09"/>
      </geometry>
      <origin rpy="0 0 0" xyz="0.125 0 0.08"/>
      <material name="chassis_color"/>
    </visual>
    <!-- Collision for the main body (Unchanged) -->
    <collision>
      <geometry>
        <box size="0.25 0.3 0.06"/>
      </geometry>
      <origin xyz="0 0 0.08"/>
    </collision>
    <!-- Inertial properties (Unchanged) -->
    <inertial>
      <mass value="4.0"/>
      <origin rpy="0 0 0" xyz="0 0 0.05"/>
      <inertia ixx="0.02" ixy="0.0" ixz="0.0" iyy="0.03" iyz="0.0" izz="0.04"/>
    </inertial>
  </link>
  <link name="front_left_wheel_link">
    <visual>
      <geometry>
        <cylinder length="0.02" radius="0.05"/>
      </geometry>
      <origin rpy="1.5708 0 0" xyz="0 0 0"/>
      <material name="wheel_color"/>
    </visual>
    <collision>
      <geometry>
        <cylinder length="0.02" radius="0.05"/>
      </geometry>
      <origin rpy="1.5708 0 0" xyz="0 0 0"/>
    </collision>
    <inertial>
      <mass value="0.5"/>
      <origin rpy="0 0 0" xyz="0 0 0"/>
      <inertia ixx="0.0005" ixy="0.0" ixz="0.0" iyy="0.0005" iyz="0.0" izz="0.001"/>
    </inertial>
  </link>
  <joint name="front_left_wheel_joint" type="continuous">
    <parent link="base_link"/>
    <child link="front_left_wheel_link"/>
    <origin rpy="0 0 0" xyz="0.075 0.15 0.05"/>
    <axis xyz="0 1 0"/>
  </joint>
  <link name="front_right_wheel_link">
    <visual>
      <geometry>
        <cylinder length="0.02" radius="0.05"/>
      </geometry>
      <origin rpy="1.5708 0 0" xyz="0 0 0"/>
      <material name="wheel_color"/>
    </visual>
    <collision>
      <geometry>
        <cylinder length="0.02" radius="0.05"/>
      </geometry>
      <origin rpy="1.5708 0 0" xyz="0 0 0"/>
    </collision>
    <inertial>
      <mass value="0.5"/>
      <origin rpy="0 0 0" xyz="0 0 0"/>
      <inertia ixx="0.0005" ixy="0.0" ixz="0.0" iyy="0.0005" iyz="0.0" izz="0.001"/>
    </inertial>
  </link>
  <joint name="front_right_wheel_joint" type="continuous">
    <parent link="base_link"/>
    <child link="front_right_wheel_link"/>
    <origin rpy="0 0 0" xyz="0.075 -0.15 0.05"/>
    <axis xyz="0 1 0"/>
  </joint>
  <link name="rear_left_wheel_link">
    <visual>
      <geometry>
        <cylinder length="0.02" radius="0.05"/>
      </geometry>
      <origin rpy="1.5708 0 0" xyz="0 0 0"/>
      <material name="wheel_color"/>
    </visual>
    <collision>
      <geometry>
        <cylinder length="0.02" radius="0.05"/>
      </geometry>
      <origin rpy="1.5708 0 0" xyz="0 0 0"/>
    </collision>
    <inertial>
      <mass value="0.5"/>
      <origin rpy="0 0 0" xyz="0 0 0"/>
      <inertia ixx="0.0005" ixy="0.0" ixz="0.0" iyy="0.0005" iyz="0.0" izz="0.001"/>
    </inertial>
  </link>
  <joint name="rear_left_wheel_joint" type="continuous">
    <parent link="base_link"/>
    <child link="rear_left_wheel_link"/>
    <origin rpy="0 0 0" xyz="-0.075 0.15 0.05"/>
    <axis xyz="0 1 0"/>
  </joint>
  <link name="rear_right_wheel_link">
    <visual>
      <geometry>
        <cylinder length="0.02" radius="0.05"/>
      </geometry>
      <origin rpy="1.5708 0 0" xyz="0 0 0"/>
      <material name="wheel_color"/>
    </visual>
    <collision>
      <geometry>
        <cylinder length="0.02" radius="0.05"/>
      </geometry>
      <origin rpy="1.5708 0 0" xyz="0 0 0"/>
    </collision>
    <inertial>
      <mass value="0.5"/>
      <origin rpy="0 0 0" xyz="0 0 0"/>
      <inertia ixx="0.0005" ixy="0.0" ixz="0.0" iyy="0.0005" iyz="0.0" izz="0.001"/>
    </inertial>
  </link>
  <joint name="rear_right_wheel_joint" type="continuous">
    <parent link="base_link"/>
    <child link="rear_right_wheel_link"/>
    <origin rpy="0 0 0" xyz="-0.075 -0.15 0.05"/>
    <axis xyz="0 1 0"/>
  </joint>
  <!-- =========================================================
       SENSOR LIDAR
       ========================================================= -->
  <link name="laser_link">
    <visual>
      <geometry>
        <cylinder length="0.02" radius="0.04"/>
      </geometry>
      <origin rpy="0 0 0" xyz="0 0 0.06"/>
      <material name="lidar_color"/>
    </visual>
  </link>
  <joint name="laser_joint" type="fixed">
    <parent link="base_link"/>
    <child link="laser_link"/>
    <origin rpy="0 0 0" xyz="0.135 0 0.06"/>
  </joint>
  <!-- =========================================================
       PLUGINS GAZEBO
       ========================================================= -->
  <!-- Dif-Drive                                               -->
  <gazebo>
    <plugin filename="libgazebo_ros_diff_drive.so" name="diff_drive">
      <left_joint>rear_left_wheel_joint</left_joint>
      <right_joint>rear_right_wheel_joint</right_joint>
      <wheel_separation>0.3</wheel_separation>
      <wheel_diameter>0.1</wheel_diameter>
      <publish_odom>true</publish_odom>
      <odom_frame>odom</odom_frame>
      <robot_base_frame>base_link</robot_base_frame>
      <cmd_vel_topic>cmd_vel</cmd_vel_topic>
      <odometry_topic>odom</odometry_topic>
      <update_rate>50</update_rate>
    </plugin>
  </gazebo>
  <!-- LIDAR como sensor ray   -->
  <gazebo reference="laser_link">
    <sensor name="lidar" type="ray">
      <update_rate>20</update_rate>
      <ray>
        <scan>
          <horizontal>
            <samples>720</samples>
            <resolution>1</resolution>
            <min_angle>-1.5708</min_angle>
            <max_angle>1.5708</max_angle>
          </horizontal>
        </scan>
        <range>
          <min>0.12</min>
          <max>6.0</max>
        </range>
      </ray>
      <plugin filename="libgazebo_ros_ray_sensor.so" name="gazebo_laser">
        <ros>
          <!-- remapea la salida interna ~/out a /scan -->
          <remapping>~/out:=scan</remapping>
        </ros>
        <!-- publica LaserScan en vez de PointCloud2 -->
        <output_type>sensor_msgs/LaserScan</output_type>
        <frame_name>laser_link</frame_name>
      </plugin>
    </sensor>
  </gazebo>
</robot>
